[2023-03-14T18:52:23.803+0530] {taskinstance.py:1083} INFO - Dependencies all met for <TaskInstance: house_usa.load_data_train scheduled__2023-03-02T03:00:00+00:00 [queued]>
[2023-03-14T18:52:23.809+0530] {taskinstance.py:1083} INFO - Dependencies all met for <TaskInstance: house_usa.load_data_train scheduled__2023-03-02T03:00:00+00:00 [queued]>
[2023-03-14T18:52:23.809+0530] {taskinstance.py:1279} INFO - 
--------------------------------------------------------------------------------
[2023-03-14T18:52:23.809+0530] {taskinstance.py:1280} INFO - Starting attempt 5 of 6
[2023-03-14T18:52:23.810+0530] {taskinstance.py:1281} INFO - 
--------------------------------------------------------------------------------
[2023-03-14T18:52:23.821+0530] {taskinstance.py:1300} INFO - Executing <Task(PythonOperator): load_data_train> on 2023-03-02 03:00:00+00:00
[2023-03-14T18:52:23.829+0530] {standard_task_runner.py:55} INFO - Started process 12983 to run task
[2023-03-14T18:52:23.832+0530] {standard_task_runner.py:82} INFO - Running: ['airflow', 'tasks', 'run', 'house_usa', 'load_data_train', 'scheduled__2023-03-02T03:00:00+00:00', '--job-id', '100', '--raw', '--subdir', 'DAGS_FOLDER/pipline.py', '--cfg-path', '/tmp/tmpn85klotl']
[2023-03-14T18:52:23.833+0530] {standard_task_runner.py:83} INFO - Job 100: Subtask load_data_train
[2023-03-14T18:52:23.871+0530] {task_command.py:388} INFO - Running <TaskInstance: house_usa.load_data_train scheduled__2023-03-02T03:00:00+00:00 [running]> on host ris
[2023-03-14T18:52:23.909+0530] {taskinstance.py:1507} INFO - Exporting the following env vars:
AIRFLOW_CTX_DAG_OWNER=RISHAB
AIRFLOW_CTX_DAG_ID=house_usa
AIRFLOW_CTX_TASK_ID=load_data_train
AIRFLOW_CTX_EXECUTION_DATE=2023-03-02T03:00:00+00:00
AIRFLOW_CTX_TRY_NUMBER=5
AIRFLOW_CTX_DAG_RUN_ID=scheduled__2023-03-02T03:00:00+00:00
[2023-03-14T18:52:23.911+0530] {taskinstance.py:1768} ERROR - Task failed with exception
Traceback (most recent call last):
  File "/home/ris/PycharmProjects/pythonProject/USA-housing/venv/lib/python3.10/site-packages/airflow/operators/python.py", line 175, in execute
    return_value = self.execute_callable()
  File "/home/ris/PycharmProjects/pythonProject/USA-housing/venv/lib/python3.10/site-packages/airflow/operators/python.py", line 192, in execute_callable
    return self.python_callable(*self.op_args, **self.op_kwargs)
TypeError: load_data() missing 1 required positional argument: 'path'
[2023-03-14T18:52:23.914+0530] {taskinstance.py:1318} INFO - Marking task as UP_FOR_RETRY. dag_id=house_usa, task_id=load_data_train, execution_date=20230302T030000, start_date=20230314T132223, end_date=20230314T132223
[2023-03-14T18:52:23.922+0530] {standard_task_runner.py:100} ERROR - Failed to execute job 100 for task load_data_train (load_data() missing 1 required positional argument: 'path'; 12983)
[2023-03-14T18:52:23.964+0530] {local_task_job.py:208} INFO - Task exited with return code 1
[2023-03-14T18:52:23.980+0530] {taskinstance.py:2578} INFO - 0 downstream tasks scheduled from follow-on schedule check
