[2023-03-10T16:06:29.000+0530] {taskinstance.py:1083} INFO - Dependencies all met for <TaskInstance: house_usa.load_data_train scheduled__2023-03-01T14:00:00+00:00 [queued]>
[2023-03-10T16:06:29.007+0530] {taskinstance.py:1083} INFO - Dependencies all met for <TaskInstance: house_usa.load_data_train scheduled__2023-03-01T14:00:00+00:00 [queued]>
[2023-03-10T16:06:29.007+0530] {taskinstance.py:1279} INFO - 
--------------------------------------------------------------------------------
[2023-03-10T16:06:29.007+0530] {taskinstance.py:1280} INFO - Starting attempt 5 of 6
[2023-03-10T16:06:29.007+0530] {taskinstance.py:1281} INFO - 
--------------------------------------------------------------------------------
[2023-03-10T16:06:29.021+0530] {taskinstance.py:1300} INFO - Executing <Task(PythonOperator): load_data_train> on 2023-03-01 14:00:00+00:00
[2023-03-10T16:06:29.032+0530] {standard_task_runner.py:55} INFO - Started process 6406 to run task
[2023-03-10T16:06:29.038+0530] {standard_task_runner.py:82} INFO - Running: ['airflow', 'tasks', 'run', 'house_usa', 'load_data_train', 'scheduled__2023-03-01T14:00:00+00:00', '--job-id', '68', '--raw', '--subdir', 'DAGS_FOLDER/pipline.py', '--cfg-path', '/tmp/tmpk1it14t7']
[2023-03-10T16:06:29.039+0530] {standard_task_runner.py:83} INFO - Job 68: Subtask load_data_train
[2023-03-10T16:06:29.106+0530] {task_command.py:388} INFO - Running <TaskInstance: house_usa.load_data_train scheduled__2023-03-01T14:00:00+00:00 [running]> on host ris
[2023-03-10T16:06:29.171+0530] {taskinstance.py:1507} INFO - Exporting the following env vars:
AIRFLOW_CTX_DAG_OWNER=RISHAB
AIRFLOW_CTX_DAG_ID=house_usa
AIRFLOW_CTX_TASK_ID=load_data_train
AIRFLOW_CTX_EXECUTION_DATE=2023-03-01T14:00:00+00:00
AIRFLOW_CTX_TRY_NUMBER=5
AIRFLOW_CTX_DAG_RUN_ID=scheduled__2023-03-01T14:00:00+00:00
[2023-03-10T16:06:29.172+0530] {taskinstance.py:1768} ERROR - Task failed with exception
Traceback (most recent call last):
  File "/home/ris/PycharmProjects/pythonProject/USA-housing/venv/lib/python3.10/site-packages/airflow/operators/python.py", line 175, in execute
    return_value = self.execute_callable()
  File "/home/ris/PycharmProjects/pythonProject/USA-housing/venv/lib/python3.10/site-packages/airflow/operators/python.py", line 192, in execute_callable
    return self.python_callable(*self.op_args, **self.op_kwargs)
TypeError: load_data() missing 1 required positional argument: 'path'
[2023-03-10T16:06:29.181+0530] {taskinstance.py:1318} INFO - Marking task as UP_FOR_RETRY. dag_id=house_usa, task_id=load_data_train, execution_date=20230301T140000, start_date=20230310T103629, end_date=20230310T103629
[2023-03-10T16:06:29.197+0530] {standard_task_runner.py:100} ERROR - Failed to execute job 68 for task load_data_train (load_data() missing 1 required positional argument: 'path'; 6406)
[2023-03-10T16:06:29.249+0530] {local_task_job.py:208} INFO - Task exited with return code 1
[2023-03-10T16:06:29.291+0530] {taskinstance.py:2578} INFO - 0 downstream tasks scheduled from follow-on schedule check
