[2023-03-14T19:42:26.183+0530] {taskinstance.py:1083} INFO - Dependencies all met for <TaskInstance: house_usa.load_data_train manual__2023-03-10T09:44:32.892768+00:00 [queued]>
[2023-03-14T19:42:26.188+0530] {taskinstance.py:1083} INFO - Dependencies all met for <TaskInstance: house_usa.load_data_train manual__2023-03-10T09:44:32.892768+00:00 [queued]>
[2023-03-14T19:42:26.189+0530] {taskinstance.py:1279} INFO - 
--------------------------------------------------------------------------------
[2023-03-14T19:42:26.189+0530] {taskinstance.py:1280} INFO - Starting attempt 2 of 6
[2023-03-14T19:42:26.189+0530] {taskinstance.py:1281} INFO - 
--------------------------------------------------------------------------------
[2023-03-14T19:42:26.199+0530] {taskinstance.py:1300} INFO - Executing <Task(PythonOperator): load_data_train> on 2023-03-10 09:44:32.892768+00:00
[2023-03-14T19:42:26.207+0530] {standard_task_runner.py:55} INFO - Started process 15593 to run task
[2023-03-14T19:42:26.211+0530] {standard_task_runner.py:82} INFO - Running: ['airflow', 'tasks', 'run', 'house_usa', 'load_data_train', 'manual__2023-03-10T09:44:32.892768+00:00', '--job-id', '123', '--raw', '--subdir', 'DAGS_FOLDER/pipline.py', '--cfg-path', '/tmp/tmpro2ptvif']
[2023-03-14T19:42:26.213+0530] {standard_task_runner.py:83} INFO - Job 123: Subtask load_data_train
[2023-03-14T19:42:26.266+0530] {task_command.py:388} INFO - Running <TaskInstance: house_usa.load_data_train manual__2023-03-10T09:44:32.892768+00:00 [running]> on host ris
[2023-03-14T19:42:26.301+0530] {taskinstance.py:1507} INFO - Exporting the following env vars:
AIRFLOW_CTX_DAG_OWNER=RISHAB
AIRFLOW_CTX_DAG_ID=house_usa
AIRFLOW_CTX_TASK_ID=load_data_train
AIRFLOW_CTX_EXECUTION_DATE=2023-03-10T09:44:32.892768+00:00
AIRFLOW_CTX_TRY_NUMBER=2
AIRFLOW_CTX_DAG_RUN_ID=manual__2023-03-10T09:44:32.892768+00:00
[2023-03-14T19:42:26.302+0530] {taskinstance.py:1768} ERROR - Task failed with exception
Traceback (most recent call last):
  File "/home/ris/PycharmProjects/pythonProject/USA-housing/venv/lib/python3.10/site-packages/airflow/operators/python.py", line 175, in execute
    return_value = self.execute_callable()
  File "/home/ris/PycharmProjects/pythonProject/USA-housing/venv/lib/python3.10/site-packages/airflow/operators/python.py", line 192, in execute_callable
    return self.python_callable(*self.op_args, **self.op_kwargs)
TypeError: load_data() missing 1 required positional argument: 'path'
[2023-03-14T19:42:26.305+0530] {taskinstance.py:1318} INFO - Marking task as UP_FOR_RETRY. dag_id=house_usa, task_id=load_data_train, execution_date=20230310T094432, start_date=20230314T141226, end_date=20230314T141226
[2023-03-14T19:42:26.312+0530] {standard_task_runner.py:100} ERROR - Failed to execute job 123 for task load_data_train (load_data() missing 1 required positional argument: 'path'; 15593)
[2023-03-14T19:42:26.341+0530] {local_task_job.py:208} INFO - Task exited with return code 1
[2023-03-14T19:42:26.374+0530] {taskinstance.py:2578} INFO - 0 downstream tasks scheduled from follow-on schedule check
