[2023-03-14T19:00:17.427+0530] {taskinstance.py:1083} INFO - Dependencies all met for <TaskInstance: house_usa.load_data_train manual__2023-03-07T12:14:28.815221+00:00 [queued]>
[2023-03-14T19:00:17.432+0530] {taskinstance.py:1083} INFO - Dependencies all met for <TaskInstance: house_usa.load_data_train manual__2023-03-07T12:14:28.815221+00:00 [queued]>
[2023-03-14T19:00:17.432+0530] {taskinstance.py:1279} INFO - 
--------------------------------------------------------------------------------
[2023-03-14T19:00:17.432+0530] {taskinstance.py:1280} INFO - Starting attempt 1 of 6
[2023-03-14T19:00:17.433+0530] {taskinstance.py:1281} INFO - 
--------------------------------------------------------------------------------
[2023-03-14T19:00:17.444+0530] {taskinstance.py:1300} INFO - Executing <Task(PythonOperator): load_data_train> on 2023-03-07 12:14:28.815221+00:00
[2023-03-14T19:00:17.451+0530] {standard_task_runner.py:55} INFO - Started process 14529 to run task
[2023-03-14T19:00:17.455+0530] {standard_task_runner.py:82} INFO - Running: ['airflow', 'tasks', 'run', 'house_usa', 'load_data_train', 'manual__2023-03-07T12:14:28.815221+00:00', '--job-id', '104', '--raw', '--subdir', 'DAGS_FOLDER/pipline.py', '--cfg-path', '/tmp/tmp4r16l0jq']
[2023-03-14T19:00:17.456+0530] {standard_task_runner.py:83} INFO - Job 104: Subtask load_data_train
[2023-03-14T19:00:17.489+0530] {task_command.py:388} INFO - Running <TaskInstance: house_usa.load_data_train manual__2023-03-07T12:14:28.815221+00:00 [running]> on host ris
[2023-03-14T19:00:17.525+0530] {taskinstance.py:1507} INFO - Exporting the following env vars:
AIRFLOW_CTX_DAG_OWNER=RISHAB
AIRFLOW_CTX_DAG_ID=house_usa
AIRFLOW_CTX_TASK_ID=load_data_train
AIRFLOW_CTX_EXECUTION_DATE=2023-03-07T12:14:28.815221+00:00
AIRFLOW_CTX_TRY_NUMBER=1
AIRFLOW_CTX_DAG_RUN_ID=manual__2023-03-07T12:14:28.815221+00:00
[2023-03-14T19:00:17.526+0530] {taskinstance.py:1768} ERROR - Task failed with exception
Traceback (most recent call last):
  File "/home/ris/PycharmProjects/pythonProject/USA-housing/venv/lib/python3.10/site-packages/airflow/operators/python.py", line 175, in execute
    return_value = self.execute_callable()
  File "/home/ris/PycharmProjects/pythonProject/USA-housing/venv/lib/python3.10/site-packages/airflow/operators/python.py", line 192, in execute_callable
    return self.python_callable(*self.op_args, **self.op_kwargs)
TypeError: load_data() missing 1 required positional argument: 'path'
[2023-03-14T19:00:17.529+0530] {taskinstance.py:1318} INFO - Marking task as UP_FOR_RETRY. dag_id=house_usa, task_id=load_data_train, execution_date=20230307T121428, start_date=20230314T133017, end_date=20230314T133017
[2023-03-14T19:00:17.537+0530] {standard_task_runner.py:100} ERROR - Failed to execute job 104 for task load_data_train (load_data() missing 1 required positional argument: 'path'; 14529)
[2023-03-14T19:00:17.586+0530] {local_task_job.py:208} INFO - Task exited with return code 1
[2023-03-14T19:00:17.619+0530] {taskinstance.py:2578} INFO - 0 downstream tasks scheduled from follow-on schedule check
