[2023-03-10T17:36:12.882+0530] {taskinstance.py:1083} INFO - Dependencies all met for <TaskInstance: house_usa.load_data_train scheduled__2023-03-01T18:00:00+00:00 [queued]>
[2023-03-10T17:36:12.890+0530] {taskinstance.py:1083} INFO - Dependencies all met for <TaskInstance: house_usa.load_data_train scheduled__2023-03-01T18:00:00+00:00 [queued]>
[2023-03-10T17:36:12.890+0530] {taskinstance.py:1279} INFO - 
--------------------------------------------------------------------------------
[2023-03-10T17:36:12.890+0530] {taskinstance.py:1280} INFO - Starting attempt 5 of 6
[2023-03-10T17:36:12.890+0530] {taskinstance.py:1281} INFO - 
--------------------------------------------------------------------------------
[2023-03-10T17:36:12.903+0530] {taskinstance.py:1300} INFO - Executing <Task(PythonOperator): load_data_train> on 2023-03-01 18:00:00+00:00
[2023-03-10T17:36:12.911+0530] {standard_task_runner.py:55} INFO - Started process 7185 to run task
[2023-03-10T17:36:12.917+0530] {standard_task_runner.py:82} INFO - Running: ['airflow', 'tasks', 'run', 'house_usa', 'load_data_train', 'scheduled__2023-03-01T18:00:00+00:00', '--job-id', '72', '--raw', '--subdir', 'DAGS_FOLDER/pipline.py', '--cfg-path', '/tmp/tmphq8g0zr0']
[2023-03-10T17:36:12.919+0530] {standard_task_runner.py:83} INFO - Job 72: Subtask load_data_train
[2023-03-10T17:36:12.983+0530] {task_command.py:388} INFO - Running <TaskInstance: house_usa.load_data_train scheduled__2023-03-01T18:00:00+00:00 [running]> on host ris
[2023-03-10T17:36:13.029+0530] {taskinstance.py:1507} INFO - Exporting the following env vars:
AIRFLOW_CTX_DAG_OWNER=RISHAB
AIRFLOW_CTX_DAG_ID=house_usa
AIRFLOW_CTX_TASK_ID=load_data_train
AIRFLOW_CTX_EXECUTION_DATE=2023-03-01T18:00:00+00:00
AIRFLOW_CTX_TRY_NUMBER=5
AIRFLOW_CTX_DAG_RUN_ID=scheduled__2023-03-01T18:00:00+00:00
[2023-03-10T17:36:13.030+0530] {taskinstance.py:1768} ERROR - Task failed with exception
Traceback (most recent call last):
  File "/home/ris/PycharmProjects/pythonProject/USA-housing/venv/lib/python3.10/site-packages/airflow/operators/python.py", line 175, in execute
    return_value = self.execute_callable()
  File "/home/ris/PycharmProjects/pythonProject/USA-housing/venv/lib/python3.10/site-packages/airflow/operators/python.py", line 192, in execute_callable
    return self.python_callable(*self.op_args, **self.op_kwargs)
TypeError: load_data() missing 1 required positional argument: 'path'
[2023-03-10T17:36:13.034+0530] {taskinstance.py:1318} INFO - Marking task as UP_FOR_RETRY. dag_id=house_usa, task_id=load_data_train, execution_date=20230301T180000, start_date=20230310T120612, end_date=20230310T120613
[2023-03-10T17:36:13.044+0530] {standard_task_runner.py:100} ERROR - Failed to execute job 72 for task load_data_train (load_data() missing 1 required positional argument: 'path'; 7185)
[2023-03-10T17:36:13.086+0530] {local_task_job.py:208} INFO - Task exited with return code 1
[2023-03-10T17:36:13.103+0530] {taskinstance.py:2578} INFO - 0 downstream tasks scheduled from follow-on schedule check
