[2023-03-14T18:17:25.332+0530] {taskinstance.py:1083} INFO - Dependencies all met for <TaskInstance: house_usa.load_data_train scheduled__2023-03-01T18:00:00+00:00 [queued]>
[2023-03-14T18:17:25.337+0530] {taskinstance.py:1083} INFO - Dependencies all met for <TaskInstance: house_usa.load_data_train scheduled__2023-03-01T18:00:00+00:00 [queued]>
[2023-03-14T18:17:25.337+0530] {taskinstance.py:1279} INFO - 
--------------------------------------------------------------------------------
[2023-03-14T18:17:25.337+0530] {taskinstance.py:1280} INFO - Starting attempt 6 of 6
[2023-03-14T18:17:25.337+0530] {taskinstance.py:1281} INFO - 
--------------------------------------------------------------------------------
[2023-03-14T18:17:25.348+0530] {taskinstance.py:1300} INFO - Executing <Task(PythonOperator): load_data_train> on 2023-03-01 18:00:00+00:00
[2023-03-14T18:17:25.355+0530] {standard_task_runner.py:55} INFO - Started process 10845 to run task
[2023-03-14T18:17:25.359+0530] {standard_task_runner.py:82} INFO - Running: ['airflow', 'tasks', 'run', 'house_usa', 'load_data_train', 'scheduled__2023-03-01T18:00:00+00:00', '--job-id', '82', '--raw', '--subdir', 'DAGS_FOLDER/pipline.py', '--cfg-path', '/tmp/tmp6t53ivgi']
[2023-03-14T18:17:25.361+0530] {standard_task_runner.py:83} INFO - Job 82: Subtask load_data_train
[2023-03-14T18:17:25.400+0530] {task_command.py:388} INFO - Running <TaskInstance: house_usa.load_data_train scheduled__2023-03-01T18:00:00+00:00 [running]> on host ris
[2023-03-14T18:17:25.435+0530] {taskinstance.py:1507} INFO - Exporting the following env vars:
AIRFLOW_CTX_DAG_OWNER=RISHAB
AIRFLOW_CTX_DAG_ID=house_usa
AIRFLOW_CTX_TASK_ID=load_data_train
AIRFLOW_CTX_EXECUTION_DATE=2023-03-01T18:00:00+00:00
AIRFLOW_CTX_TRY_NUMBER=6
AIRFLOW_CTX_DAG_RUN_ID=scheduled__2023-03-01T18:00:00+00:00
[2023-03-14T18:17:25.436+0530] {taskinstance.py:1768} ERROR - Task failed with exception
Traceback (most recent call last):
  File "/home/ris/PycharmProjects/pythonProject/USA-housing/venv/lib/python3.10/site-packages/airflow/operators/python.py", line 175, in execute
    return_value = self.execute_callable()
  File "/home/ris/PycharmProjects/pythonProject/USA-housing/venv/lib/python3.10/site-packages/airflow/operators/python.py", line 192, in execute_callable
    return self.python_callable(*self.op_args, **self.op_kwargs)
TypeError: load_data() missing 1 required positional argument: 'path'
[2023-03-14T18:17:25.440+0530] {taskinstance.py:1318} INFO - Marking task as FAILED. dag_id=house_usa, task_id=load_data_train, execution_date=20230301T180000, start_date=20230314T124725, end_date=20230314T124725
[2023-03-14T18:17:25.447+0530] {standard_task_runner.py:100} ERROR - Failed to execute job 82 for task load_data_train (load_data() missing 1 required positional argument: 'path'; 10845)
[2023-03-14T18:17:25.489+0530] {local_task_job.py:208} INFO - Task exited with return code 1
[2023-03-14T18:17:25.507+0530] {taskinstance.py:2578} INFO - 0 downstream tasks scheduled from follow-on schedule check
