[2023-03-14T20:03:33.680+0530] {taskinstance.py:1083} INFO - Dependencies all met for <TaskInstance: house_usa.load_data_train manual__2023-03-07T12:21:39.574208+00:00 [queued]>
[2023-03-14T20:03:33.686+0530] {taskinstance.py:1083} INFO - Dependencies all met for <TaskInstance: house_usa.load_data_train manual__2023-03-07T12:21:39.574208+00:00 [queued]>
[2023-03-14T20:03:33.686+0530] {taskinstance.py:1279} INFO - 
--------------------------------------------------------------------------------
[2023-03-14T20:03:33.686+0530] {taskinstance.py:1280} INFO - Starting attempt 4 of 6
[2023-03-14T20:03:33.686+0530] {taskinstance.py:1281} INFO - 
--------------------------------------------------------------------------------
[2023-03-14T20:03:33.696+0530] {taskinstance.py:1300} INFO - Executing <Task(PythonOperator): load_data_train> on 2023-03-07 12:21:39.574208+00:00
[2023-03-14T20:03:33.703+0530] {standard_task_runner.py:55} INFO - Started process 15896 to run task
[2023-03-14T20:03:33.708+0530] {standard_task_runner.py:82} INFO - Running: ['airflow', 'tasks', 'run', 'house_usa', 'load_data_train', 'manual__2023-03-07T12:21:39.574208+00:00', '--job-id', '135', '--raw', '--subdir', 'DAGS_FOLDER/pipline.py', '--cfg-path', '/tmp/tmp7iohp1er']
[2023-03-14T20:03:33.710+0530] {standard_task_runner.py:83} INFO - Job 135: Subtask load_data_train
[2023-03-14T20:03:33.760+0530] {task_command.py:388} INFO - Running <TaskInstance: house_usa.load_data_train manual__2023-03-07T12:21:39.574208+00:00 [running]> on host ris
[2023-03-14T20:03:33.795+0530] {taskinstance.py:1507} INFO - Exporting the following env vars:
AIRFLOW_CTX_DAG_OWNER=RISHAB
AIRFLOW_CTX_DAG_ID=house_usa
AIRFLOW_CTX_TASK_ID=load_data_train
AIRFLOW_CTX_EXECUTION_DATE=2023-03-07T12:21:39.574208+00:00
AIRFLOW_CTX_TRY_NUMBER=4
AIRFLOW_CTX_DAG_RUN_ID=manual__2023-03-07T12:21:39.574208+00:00
[2023-03-14T20:03:33.796+0530] {taskinstance.py:1768} ERROR - Task failed with exception
Traceback (most recent call last):
  File "/home/ris/PycharmProjects/pythonProject/USA-housing/venv/lib/python3.10/site-packages/airflow/operators/python.py", line 175, in execute
    return_value = self.execute_callable()
  File "/home/ris/PycharmProjects/pythonProject/USA-housing/venv/lib/python3.10/site-packages/airflow/operators/python.py", line 192, in execute_callable
    return self.python_callable(*self.op_args, **self.op_kwargs)
TypeError: load_data() missing 1 required positional argument: 'path'
[2023-03-14T20:03:33.799+0530] {taskinstance.py:1318} INFO - Marking task as UP_FOR_RETRY. dag_id=house_usa, task_id=load_data_train, execution_date=20230307T122139, start_date=20230314T143333, end_date=20230314T143333
[2023-03-14T20:03:33.807+0530] {standard_task_runner.py:100} ERROR - Failed to execute job 135 for task load_data_train (load_data() missing 1 required positional argument: 'path'; 15896)
[2023-03-14T20:03:33.837+0530] {local_task_job.py:208} INFO - Task exited with return code 1
[2023-03-14T20:03:33.871+0530] {taskinstance.py:2578} INFO - 0 downstream tasks scheduled from follow-on schedule check
